I'm sorry, but an uncaught exception occurred.

While running game code:
  File "game/script5-1.rpy", line 7, in script
    d "对了，去年你为什么没有参加南星计划啊？"
Exception: Sayer 'd' is not defined.

-- Full Traceback ------------------------------------------------------------

Full traceback:
  File "game/script5-1.rpy", line 7, in script
    d "对了，去年你为什么没有参加南星计划啊？"
  File "renpy/ast.py", line 680, in execute
    who = eval_who(self.who, self.who_fast)
  File "renpy/ast.py", line 574, in eval_who
    raise Exception("Sayer '%s' is not defined." % who)
Exception: Sayer 'd' is not defined.

Windows-10-10.0.19041
Ren'Py 7.4.4.1439
对绿色我们永远向往 0.5.0
Wed May 12 17:36:07 2021
